{
   "CVE_data_meta" : {
      "ASSIGNER" : "cve@mitre.org",
      "ID" : "CVE-2010-3494",
      "STATE" : "PUBLIC"
   },
   "affects" : {
      "vendor" : {
         "vendor_data" : [
            {
               "product" : {
                  "product_data" : [
                     {
                        "product_name" : "n/a",
                        "version" : {
                           "version_data" : [
                              {
                                 "version_value" : "n/a"
                              }
                           ]
                        }
                     }
                  ]
               },
               "vendor_name" : "n/a"
            }
         ]
      }
   },
   "data_format" : "MITRE",
   "data_type" : "CVE",
   "data_version" : "4.0",
   "description" : {
      "description_data" : [
         {
            "lang" : "eng",
            "value" : "Race condition in the FTPHandler class in ftpserver.py in pyftpdlib before 0.5.2 allows remote attackers to cause a denial of service (daemon outage) by establishing and then immediately closing a TCP connection, leading to the accept function having an unexpected value of None for the address, or an ECONNABORTED, EAGAIN, or EWOULDBLOCK error, a related issue to CVE-2010-3492."
         }
      ]
   },
   "problemtype" : {
      "problemtype_data" : [
         {
            "description" : [
               {
                  "lang" : "eng",
                  "value" : "n/a"
               }
            ]
         }
      ]
   },
   "references" : {
      "reference_data" : [
         {
            "url" : "http://www.openwall.com/lists/oss-security/2010/09/09/6"
         },
         {
            "url" : "http://www.openwall.com/lists/oss-security/2010/09/11/2"
         },
         {
            "url" : "http://www.openwall.com/lists/oss-security/2010/09/22/3"
         },
         {
            "url" : "http://www.openwall.com/lists/oss-security/2010/09/24/3"
         },
         {
            "url" : "http://bugs.python.org/issue6706"
         },
         {
            "url" : "https://bugs.launchpad.net/zodb/+bug/135108"
         },
         {
            "url" : "http://code.google.com/p/pyftpdlib/issues/detail?id=104"
         },
         {
            "url" : "http://code.google.com/p/pyftpdlib/issues/detail?id=105"
         },
         {
            "url" : "http://code.google.com/p/pyftpdlib/source/browse/trunk/HISTORY"
         },
         {
            "url" : "http://code.google.com/p/pyftpdlib/source/detail?r=556"
         },
         {
            "url" : "http://code.google.com/p/pyftpdlib/source/diff?spec=svn556&r=556&format=side&path=/trunk/pyftpdlib/ftpserver.py"
         }
      ]
   }
}
