{
    "CVE_data_meta": {
        "ASSIGNER": "cve@mitre.org",
        "ID": "CVE-2019-18348",
        "STATE": "PUBLIC"
    },
    "affects": {
        "vendor": {
            "vendor_data": [
                {
                    "product": {
                        "product_data": [
                            {
                                "product_name": "n/a",
                                "version": {
                                    "version_data": [
                                        {
                                            "version_value": "n/a"
                                        }
                                    ]
                                }
                            }
                        ]
                    },
                    "vendor_name": "n/a"
                }
            ]
        }
    },
    "data_format": "MITRE",
    "data_type": "CVE",
    "data_version": "4.0",
    "description": {
        "description_data": [
            {
                "lang": "eng",
                "value": "An issue was discovered in urllib2 in Python 2.x through 2.7.17 and urllib in Python 3.x through 3.8.0. CRLF injection is possible if the attacker controls a url parameter, as demonstrated by the first argument to urllib.request.urlopen with \\r\\n (specifically in the host component of a URL) followed by an HTTP header. This is similar to the CVE-2019-9740 query string issue and the CVE-2019-9947 path string issue. (This is not exploitable when glibc has CVE-2016-10739 fixed.)"
            }
        ]
    },
    "problemtype": {
        "problemtype_data": [
            {
                "description": [
                    {
                        "lang": "eng",
                        "value": "n/a"
                    }
                ]
            }
        ]
    },
    "references": {
        "reference_data": [
            {
                "url": "https://bugzilla.redhat.com/show_bug.cgi?id=1727276",
                "refsource": "MISC",
                "name": "https://bugzilla.redhat.com/show_bug.cgi?id=1727276"
            },
            {
                "url": "https://bugs.python.org/issue30458#msg347282",
                "refsource": "MISC",
                "name": "https://bugs.python.org/issue30458#msg347282"
            }
        ]
    }
}