{
   "CVE_data_meta" : {
      "ASSIGNER" : "cve@mitre.org",
      "ID" : "CVE-2013-4260",
      "STATE" : "PUBLIC"
   },
   "affects" : {
      "vendor" : {
         "vendor_data" : [
            {
               "product" : {
                  "product_data" : [
                     {
                        "product_name" : "n/a",
                        "version" : {
                           "version_data" : [
                              {
                                 "version_value" : "n/a"
                              }
                           ]
                        }
                     }
                  ]
               },
               "vendor_name" : "n/a"
            }
         ]
      }
   },
   "data_format" : "MITRE",
   "data_type" : "CVE",
   "data_version" : "4.0",
   "description" : {
      "description_data" : [
         {
            "lang" : "eng",
            "value" : "lib/ansible/playbook/__init__.py in Ansible 1.2.x before 1.2.3, when playbook does not run due to an error, allows local users to overwrite arbitrary files via a symlink attack on a retry file with a predictable name in /var/tmp/ansible/."
         }
      ]
   },
   "problemtype" : {
      "problemtype_data" : [
         {
            "description" : [
               {
                  "lang" : "eng",
                  "value" : "n/a"
               }
            ]
         }
      ]
   },
   "references" : {
      "reference_data" : [
         {
            "url" : "https://bugzilla.redhat.com/show_bug.cgi?id=998227"
         },
         {
            "url" : "https://groups.google.com/forum/#!topic/ansible-project/UVDYW0HGcNg"
         },
         {
            "url" : "http://www.ansible.com/security"
         },
         {
            "url" : "https://exchange.xforce.ibmcloud.com/vulnerabilities/86898"
         }
      ]
   }
}
